<?xml version="1.0"?>
<robot name="botpj2v1" xmlns:xacro="http://ros.org/wiki/xacro">
    <material name="white">
        <color rgba="1 1 1 1" />
    </material>

    <material name="orange">
        <color rgba="1 0.3 0.1 1"/>
    </material>

    <material name="blue">
        <color rgba="0.2 0.2 1 1"/>
    </material>

    <material name="black">
        <color rgba="0 0 0 1"/>
    </material>
   
 <material name="red">
     <color rgba="1 0 0 1"/>
 </material>
    
    <!-- BASE LINK -->
    <link name="base_link">
    <origin xyz="0 0 0" rpy="0 0 0"/>
    </link>
    

  <!-- Link 0(baselink) -->
  <link name="link_0">
    <visual>
      <geometry>
        <mesh filename="/home/mikepzaza/Desktop/project2/src/articubot_two/baselink.dae" scale="1 1 1"/>
      </geometry>
    </visual>
    <collision>
      <geometry>
        <mesh filename="/home/mikepzaza/Desktop/project2/src/articubot_two/baselink.dae" scale="1 1 1"/>
      </geometry>
    </collision>
    <xacro:inertial_box mass="1.5" x="0.480" y="0.510" z="0.33">
        <origin xyz="0 0 0" rpy="0 0 0"/>
    </xacro:inertial_box>
  </link>
    <gazebo reference="link_0">
    <material>Gazebo/White</material>
    </gazebo>


  <!-- Joint between base_link and link_0  -->
  <joint name="joint_0" type="fixed">
    <parent link="base_link"/>
    <child link="link_0"/>
    <origin xyz="-0.097289 -0.049023 -0.03252" rpy="0 0 0"/>
  </joint>         

  <!-- Link 1 (T1)-->
  <link name="link_1">
    <visual>
      <geometry>
        <mesh filename="/home/mikepzaza/Desktop/project2/src/articubot_two/T1V2.dae" scale="1 1 1"/>
      </geometry>
    </visual>
    <collision>
      <geometry>
        <mesh filename="/home/mikepzaza/Desktop/project2/src/articubot_two/T1.dae" scale="1 1 1"/>
      </geometry>
    </collision>
    <xacro:inertial_box mass="0.1" x="0.005" y="0.14" z="0.08">
        <origin xyz="0 0 0" rpy="0 0 0"/>
    </xacro:inertial_box>
  </link>
    <gazebo reference="link_1">
    <material>Gazebo/White</material>
    </gazebo>
  

  <!-- Joint between link_0 and base_link -->
  <joint name="joint_1" type="revolute">
    <parent link="base_link"/>
    <child link="link_1"/>
    <origin xyz="0.073 0.05597 0.02748" rpy="0 0 0"/>
    <axis xyz="1 0 0"/>
    <limit effort="5.0" velocity="1.0" lower="-0.540" upper="0.540"/>
  </joint>

  <!-- Link 2 (T2)-->
  <link name="link_2">
    <visual>
      <geometry>
        <mesh filename="/home/mikepzaza/Desktop/project2/src/articubot_two/T2V2.dae" scale="1 1 1"/>
      </geometry>
    </visual>
    <collision>
      <geometry>
        <mesh filename="/home/mikepzaza/Desktop/project2/src/articubot_two/T2V2.dae" scale="1 1 1"/>
      </geometry>
    </collision>
    <xacro:inertial_box mass="0.1" x="0.005" y="0.14" z="0.08">
        <origin xyz="0 0 0" rpy="0 0 0"/>
    </xacro:inertial_box>
  </link>
    <gazebo reference="link_2">
    <material>Gazebo/White</material>
    </gazebo>

  <!-- Joint between link_1 and base_link -->
  <joint name="joint_2" type="revolute">
    <parent link="base_link"/>
    <child link="link_2"/>
    <origin xyz="-0.278289 0.055976 0.02748" rpy="0 0 0"/>
    <axis xyz="1 0 0"/>
    <limit effort="5.0" velocity="1.0" lower="-0.540" upper="0.540"/>
  </joint>

  <!-- Link 6 (W1)-->
  <link name="link_6">
    <visual>
      <geometry>
        <mesh filename="/home/mikepzaza/Desktop/project2/src/articubot_two/W1V2.dae" scale="1 1 1"/>
      </geometry>
    </visual>
    <collision>
      <geometry>
        <cylinder radius="0.06" length="0.06"/>
      </geometry>
    </collision>
    <xacro:inertial_cylinder mass="0.15" length="0.06" radius="0.06">
        <origin xyz="0 0 0" rpy="0 0 0"/>
    </xacro:inertial_cylinder>
  </link>
    <gazebo reference="link_6">
    <material>Gazebo/White</material>
    </gazebo>


  <!-- Joint between link_0 and link_6 -->
  <joint name="joint_6" type="continuous">
    <parent link="base_link"/>
    <child link="link_6"/>
    <origin xyz="-0.312 -0.214023 -0.03252" rpy="0 0 0"/>
    <axis xyz="1 0 0"/>
  </joint>


 <!-- Link 6 Clone (W3)-->
  <link name="link_6_clone">
    <visual>
      <geometry>
        <mesh filename="/home/mikepzaza/Desktop/project2/src/articubot_two/Wh1.dae" scale="1 1 1"/>
      </geometry>
    </visual>
    <collision>
      <geometry>
          <cylinder radius="0.06" length="0.06"/>
      </geometry>
    </collision>
    <xacro:inertial_cylinder mass="0.15" length="0.06" radius="0.06">
        <origin xyz="0 0 0" rpy="0 0 0"/>
    </xacro:inertial_cylinder>
  </link>
    <gazebo reference="link_6_clone">
    <material>Gazebo/White</material>
    </gazebo>


  <!-- Joint between base_link and link_6_clone -->
  <joint name="joint_6_clone" type="continuous">
    <parent link="link_2"/>
    <child link="link_6_clone"/>
    <origin xyz="-0.034 -0.07 -0.06" rpy="0 0 0"/>
    <axis xyz="1 0 0"/>
  </joint>

  <!-- Link 6 Clone Clone (W5) -->
  <link name="link_6_clone_clone">
    <visual>
      <geometry>
        <mesh filename="/home/mikepzaza/Desktop/project2/src/articubot_two/Wh1.dae" scale="1 1 1"/>
      </geometry>
    </visual>
    <collision>
      <geometry>
          <cylinder radius="0.06" length="0.06"/>
      </geometry>
    </collision>
    <xacro:inertial_cylinder mass="0.15" length="0.06" radius="0.06">
        <origin xyz="0 0 0" rpy="0 0 0"/>
    </xacro:inertial_cylinder>
  </link>
    <gazebo reference="link_6_clone_clone">
    <material>Gazebo/White</material>
    </gazebo>


  <!-- Joint between link_6_clone and link_6_clone_clone -->
  <joint name="joint_6_clone_clone" type="continuous">
    <parent link="link_2"/>
    <child link="link_6_clone_clone"/>
    <origin xyz="-0.034 0.07 -0.06" rpy="0 0 0"/>
    <axis xyz="1 0 0"/>
  </joint>

  <!-- Link 7 (W2)-->
  <link name="link_7">
    <visual>
      <geometry>
        <mesh filename="/home/mikepzaza/Desktop/project2/src/articubot_two/W2V2.dae" scale="1 1 1"/>
      </geometry>
    </visual>
    <collision>
      <geometry>
          <cylinder radius="0.06" length="0.06"/>
      </geometry>
    </collision>
    <xacro:inertial_cylinder mass="0.15" length="0.06" radius="0.06">
        <origin xyz="0 0 0" rpy="0 0 0"/>
    </xacro:inertial_cylinder>
  </link>
    <gazebo reference="link_7">
    <material>Gazebo/White</material>
    </gazebo>

  <!-- Joint between base_link and link_7 -->
  <joint name="joint_7" type="continuous">
    <parent link="base_link"/>
    <child link="link_7"/>
    <origin xyz="0.106 -0.213773 -0.03252" rpy="0 0 0"/>
    <axis xyz="1 0 0"/>
  </joint>

  <!-- Link 7 Clone (W4)-->
  <link name="link_7_clone">
    <visual>
      <geometry>
        <mesh filename="/home/mikepzaza/Desktop/project2/src/articubot_two/W2.dae" scale="1 1 1"/>
      </geometry>
    </visual>
    <collision>
      <geometry>
          <cylinder radius="0.06" length="0.06"/>
      </geometry>
    </collision>
    <xacro:inertial_cylinder mass="0.15" length="0.06" radius="0.06">
        <origin xyz="0 0 0" rpy="0 0 0"/>
    </xacro:inertial_cylinder>
  </link>
    <gazebo reference="link_7_clone">
    <material>Gazebo/White</material>
    </gazebo>

  <!-- Joint between link_7 and link_7_clone -->
  <joint name="joint_7_clone" type="continuous">
    <parent link="link_1"/>
    <child link="link_7_clone"/>
    <origin xyz="0.035 -0.07 -0.06" rpy="0 0 0"/>
    <axis xyz="1 0 0"/>
  </joint>

  <!-- Link 7 Clone Clone (W6)-->
  <link name="link_7_clone_clone">
    <visual>
      <geometry>
        <mesh filename="/home/mikepzaza/Desktop/project2/src/articubot_two/W2.dae" scale="1 1 1"/>
      </geometry>
    </visual>
    <collision>
      <geometry>
          <cylinder radius="0.06" length="0.06"/>
      </geometry>
    </collision>
    <xacro:inertial_cylinder mass="0.15" length="0.06" radius="0.06">
        <origin xyz="0 0 0" rpy="0 0 0"/>
    </xacro:inertial_cylinder>
  </link>
    <gazebo reference="link_7_clone_clone">
    <material>Gazebo/White</material>
    </gazebo>

  <!-- Joint between link_7_clone and link_7_clone_clone -->
  <joint name="joint_7_clone_clone" type="continuous">
    <parent link="link_1"/>
    <child link="link_7_clone_clone"/>
    <origin xyz="0.035 0.07 -0.06" rpy="0 0 0"/>
    <axis xyz="1 0 0"/>
  </joint>

 <!-- Link 8 (A1)-->
  <link name="link_8">
    <visual>
      <geometry>
        <mesh filename="/home/mikepzaza/Desktop/project2/src/articubot_two/A1V2.dae" scale="1 1 1"/>
      </geometry>
    </visual>
    <collision>
      <geometry>
        <mesh filename="/home/mikepzaza/Desktop/project2/src/articubot_two/A1V2.dae" scale="1 1 1"/>
      </geometry>
    </collision>
    <xacro:inertial_box mass="0.1" x="0.015" y="0.085" z="0.05">
        <origin xyz="0 0 0" rpy="0 0 0"/>
    </xacro:inertial_box>
    </link>
    <gazebo reference="link_8">
    <material>Gazebo/White</material>
    </gazebo>


  <!-- Joint between link_0 and link_8 -->
  <joint name="joint_8" type="revolute">
    <parent link="base_link"/>
    <child link="link_8"/>
    <origin xyz="-0.247521 -0.078748 0.018452" rpy="0 0 0"/>
    <axis xyz="1 0 0"/>
    <limit effort="5.0" velocity="1.0" lower="-1.57" upper="1.57"/>
  </joint>

  <!-- Link 9 (A2)-->
  <link name="link_9">
    <visual>
      <geometry>
        <mesh filename="/home/mikepzaza/Desktop/project2/src/articubot_two/A2.dae" scale="1 1 1"/>
      </geometry>
    </visual>
    <collision>
      <geometry>
        <mesh filename="/home/mikepzaza/Desktop/project2/src/articubot_two/A2.dae" scale="1 1 1"/>
      </geometry>
    </collision>
    <xacro:inertial_box mass="0.125" x="0.015" y="0.180" z="0.1">
        <origin xyz="0 0 0" rpy="0 0 0"/>
    </xacro:inertial_box> 
  </link>
    <gazebo reference="link_9">
    <material>Gazebo/White</material>
    </gazebo>


  <!-- Joint between link_8 and link_9 -->
  <joint name="joint_9" type="revolute">
    <parent link="link_8"/>
    <child link="link_9"/>
    <origin xyz="0.015 -0.055 0" rpy="0 0 0"/>
    <axis xyz="1 0 0"/>
    <limit effort="5.0" velocity="1.0" lower="-1" upper="1.57"/>
  </joint>


  <!-- Link 10 (A3)-->
  <link name="link_10">
    <visual>
      <geometry>
        <mesh filename="/home/mikepzaza/Desktop/project2/src/articubot_two/A3.dae" scale="1 1 1"/>
      </geometry>
    </visual>
    <collision>
      <geometry>
        <mesh filename="/home/mikepzaza/Desktop/project2/src/articubot_two/A3.dae" scale="1 1 1"/>
      </geometry>
    </collision>
    <xacro:inertial_box mass="0.1" x="0.015" y="0.180" z="0.1">
        <origin xyz="0 0 0" rpy="0 0 0"/>
    </xacro:inertial_box>
  </link>
    <gazebo reference="link_10">
    <material>Gazebo/White</material>
    </gazebo>

  <!-- Joint between link_9 and link_10 -->
  <joint name="joint_10" type="prismatic">
    <parent link="link_9"/>
    <child link="link_10"/>
    <origin xyz="0.28 -0.0125 0" rpy="0 0 0"/>
    <axis xyz="1 0 0"/>
   <limit lower="-0.2625" upper="0" effort="10.0" velocity="0.5"/>
   <dynamics damping="0.1" friction="0.05"/>
  </joint>


</robot>
