<?xml version="1.0"?>
<robot xmlns:xacro="http://www.ros.org/wiki/xacro" >
<xacro:include filename="inertial_macros.xacro" />

    <material name="white">
        <color rgba="1 1 1 1" />
    </material>

    <material name="orange">
        <color rgba="1 0.3 0.1 1"/>
    </material>

    <material name="blue">
        <color rgba="0.2 0.2 1 1"/>
    </material>

    <material name="black">
        <color rgba="0 0 0 1"/>
    </material>
   
 <material name="red">
     <color rgba="1 0 0 1"/>
 </material>
    
  <!-- BASE LINK -->
  <link name="base_link">
  </link>
    
  <!-- BASE_FOOTPRINT LINK -->

  <joint name="base_footprint_joint" type="fixed">
    <parent link="base_link"/>
    <child link="base_footprint"/>
    <origin xyz="0 0 0" rpy="0 0 0"/>
  </joint>

  <link name="base_footprint">
  </link>

  <!-- Joint between base_link and link_0  -->
  <joint name="joint_0" type="fixed">
    <parent link="base_link"/>
    <child link="link_0"/>
    <origin xyz="0 0 0" rpy="0 0 0"/>  
  </joint>        


  <!-- Link 0(baselink) -->
  <link name="link_0">
    <visual>
      <geometry>
        <mesh filename="file:///home/mikepzaza/Desktop/project2/src/articubot_two/baselink.dae" scale="1 1 1"/>
      </geometry>
    </visual>
    <collision>
      <geometry>
        <mesh filename="file:///home/mikepzaza/Desktop/project2/src/articubot_two/baselink.dae" scale="1 1 1"/>
      </geometry>
    </collision>
    <xacro:inertial_box mass="4" x="0.480" y="0.510" z="0.33">
        <origin xyz="0 0 0" rpy="0 0 0"/>
    </xacro:inertial_box>
  </link>
    <gazebo reference="link_0">
    <material>Gazebo/White</material>
    </gazebo>


  <!-- Joint between link_0 and base_link -->
  <joint name="joint_1" type="revolute">
    <parent link="base_link"/>
    <child link="link_1"/>
    <origin xyz="0.170 0.08 0.06" rpy="0 0 0"/>
    <axis xyz="1 0 0"/>
    <limit effort="5.0" velocity="1.0" lower="-0.540" upper="0.540"/>
  </joint>

  <!-- Link 1 (T1)-->
  <link name="link_1">
    <visual>
      <geometry>
        <mesh filename="file:///home/mikepzaza/Desktop/project2/src/articubot_two/T1V2.dae" scale="1 1 1"/>
      </geometry>
    </visual>
    <collision>
      <geometry>
        <mesh filename="file:///home/mikepzaza/Desktop/project2/src/articubot_two/T1.dae" scale="1 1 1"/>
      </geometry>
    </collision>
    <xacro:inertial_box mass="0.8" x="0.005" y="0.14" z="0.08">
        <origin xyz="0 0 0" rpy="0 0 0"/>
    </xacro:inertial_box>
  </link>
    <gazebo reference="link_1">
    <material>Gazebo/White</material>
    </gazebo>
  
  <!-- Joint between link_1 and base_link -->
  <joint name="joint_2" type="revolute">
    <parent link="base_link"/>
    <child link="link_2"/>
    <origin xyz="-0.181 0.08 0.06" rpy="0 0 0"/>
    <axis xyz="1 0 0"/>
    <limit effort="5.0" velocity="1.0" lower="-0.540" upper="0.540"/>
  </joint>

  <!-- Link 2 (T2)-->
  <link name="link_2">
    <visual>
      <geometry>
        <mesh filename="file:///home/mikepzaza/Desktop/project2/src/articubot_two/T2V2.dae" scale="1 1 1"/>
      </geometry>
    </visual>
    <collision>
      <geometry>
        <mesh filename="file:///home/mikepzaza/Desktop/project2/src/articubot_two/T2V2.dae" scale="1 1 1"/>
      </geometry>
    </collision>
    <xacro:inertial_box mass="0.8" x="0.005" y="0.14" z="0.08">
        <origin xyz="0 0 0" rpy="0 0 0"/>
    </xacro:inertial_box>
  </link>
    <gazebo reference="link_2">
    <material>Gazebo/White</material>
    </gazebo>

  <!-- Joint between link_0 and link_6 -->
  <joint name="joint_6" type="continuous">
    <parent link="base_link"/>
    <child link="link_6"/>
    <origin xyz="-0.215 -0.16 0" rpy="0 -${pi/2}  0"/>
    <axis xyz="0 0 1"/>
  </joint>

  <!-- Link 6 (W1)-->
  <link name="link_6">
    <visual>
      <geometry>
        <cylinder radius="0.06" length="0.06"/>
      </geometry>
    </visual>
    <collision>
      <geometry>
        <cylinder radius="0.06" length="0.06"/>
      </geometry>
    </collision>
    <xacro:inertial_cylinder mass="0.3" length="0.06" radius="0.06">
        <origin xyz="0 0 0" rpy="0 0 0"/>
    </xacro:inertial_cylinder>
  </link>
    <gazebo reference="link_6">
    <material>Gazebo/White</material>
    </gazebo>

  <!-- Joint between base_link and link_6_clone -->
  <joint name="joint_6_clone" type="continuous">
    <parent link="link_2"/>
    <child link="link_6_clone"/>
    <origin xyz="-0.035 -0.07 -0.06" rpy="0 1.57 0"/>
    <axis xyz="0 0 1"/>
  </joint>

 <!-- Link 6 Clone (W3)-->
  <link name="link_6_clone">
    <visual>
      <geometry>
        <cylinder radius="0.06" length="0.06"/>
      </geometry>
    </visual>
    <collision>
      <geometry>
          <cylinder radius="0.06" length="0.06"/>
      </geometry>
    </collision>
    <xacro:inertial_cylinder mass="0.3" length="0.06" radius="0.06">
        <origin xyz="0 0 0" rpy="0 0 0"/>
    </xacro:inertial_cylinder>
  </link>
    <gazebo reference="link_6_clone">
    <material>Gazebo/White</material>
    </gazebo>

  <!-- Joint between link_2 and link_6_clone_clone -->
  <joint name="joint_6_clone_clone" type="continuous">
    <parent link="link_2"/>
    <child link="link_6_clone_clone"/>
    <origin xyz="-0.035 0.07 -0.06" rpy="0 1.57 0"/>
    <axis xyz="0 0 1"/>
  </joint>

  <!-- Link 6 Clone Clone (W5) -->
  <link name="link_6_clone_clone">
    <visual>
      <geometry>
        <cylinder radius="0.06" length="0.06"/>
      </geometry>
    </visual>
    <collision>
      <geometry>
          <cylinder radius="0.06" length="0.06"/>
      </geometry>
    </collision>
    <xacro:inertial_cylinder mass="0.3" length="0.06" radius="0.06">
        <origin xyz="0 0 0" rpy="0 0 0"/>
    </xacro:inertial_cylinder>
  </link>
    <gazebo reference="link_6_clone_clone">
    <material>Gazebo/White</material>
    </gazebo>

  <!-- Joint between base_link and link_7 -->
  <joint name="joint_7" type="continuous">
    <parent link="base_link"/>
    <child link="link_7"/>
    <origin xyz="0.205 -0.16 0" rpy="0 1.57 0"/>
    <axis xyz="0 0 1"/>
  </joint>

  <!-- Link 7 (W2)-->
  <link name="link_7">
    <visual>
      <geometry>
        <cylinder radius="0.06" length="0.06"/>
      </geometry>
    </visual>
    <collision>
      <geometry>
          <cylinder radius="0.06" length="0.06"/>
      </geometry>
    </collision>
    <xacro:inertial_cylinder mass="0.3" length="0.06" radius="0.06">
        <origin xyz="0 0 0" rpy="0 0 0"/>
    </xacro:inertial_cylinder>
  </link>
    <gazebo reference="link_7">
    <material>Gazebo/White</material>
    </gazebo>

  <!-- Joint between link_1 and link_7_clone -->
  <joint name="joint_7_clone" type="continuous">
    <parent link="link_1"/>
    <child link="link_7_clone"/>
    <origin xyz="0.035 -0.07 -0.06" rpy="0 1.57 0"/>
    <axis xyz="0 0 1"/>
  </joint>

  <!-- Link 7 Clone (W4)-->
  <link name="link_7_clone">
    <visual>
      <geometry>
        <cylinder radius="0.06" length="0.06"/>
      </geometry>
    </visual>
    <collision>
      <geometry>
          <cylinder radius="0.06" length="0.06"/>
      </geometry>
    </collision>
    <xacro:inertial_cylinder mass="0.3" length="0.06" radius="0.06">
        <origin xyz="0 0 0" rpy="0 0 0"/>
    </xacro:inertial_cylinder>
  </link>
    <gazebo reference="link_7_clone">
    <material>Gazebo/White</material>
    </gazebo>

  <!-- Joint between link_1 and link_7_clone_clone -->
  <joint name="joint_7_clone_clone" type="continuous">
    <parent link="link_1"/>
    <child link="link_7_clone_clone"/>
    <origin xyz="0.035 0.07 -0.06" rpy="0 1.57 0"/>
    <axis xyz="0 0 1"/>
  </joint>

  <!-- Link 7 Clone Clone (W6)-->
  <link name="link_7_clone_clone">
    <visual>
      <geometry>
        <cylinder radius="0.06" length="0.06"/>
      </geometry>
    </visual>
    <collision>
      <geometry>
          <cylinder radius="0.06" length="0.06"/>
      </geometry>
    </collision>
    <xacro:inertial_cylinder mass="0.3" length="0.06" radius="0.06">
        <origin xyz="0 0 0" rpy="0 0 0"/>
    </xacro:inertial_cylinder>
  </link>
    <gazebo reference="link_7_clone_clone">
    <material>Gazebo/White</material>
    </gazebo>


</robot>
